<?xml version="1.0" ?>
<robot name="minmax" xmlns:xacro="http://www.ros.org/wiki/xacro">

<xacro:include filename="$(find minmax_description)/urdf/materials.xacro" />
<xacro:include filename="$(find minmax_description)/urdf/minmax.trans" />
<xacro:include filename="$(find minmax_description)/urdf/minmax.gazebo" />
<link name="base_link">
  <inertial>
    <origin xyz="-4.289664982796383e-05 0.03267641514636162 0.023507658958163202" rpy="0 0 0"/>
    <mass value="2.1093773604458343"/>
    <inertia ixx="0.070945" iyy="0.017133" izz="0.08592" ixy="1.2e-05" iyz="-0.001355" ixz="5e-06"/>
  </inertial>
  <visual>
    <origin xyz="0 0 0" rpy="0 0 0"/>
    <geometry>
      <mesh filename="package://minmax_description/meshes/base_link.stl" scale="0.001 0.001 0.001"/>
    </geometry>
    <material name="silver"/>
  </visual>
  <collision>
    <origin xyz="0 0 0" rpy="0 0 0"/>
    <geometry>
      <mesh filename="package://minmax_description/meshes/base_link.stl" scale="0.001 0.001 0.001"/>
    </geometry>
  </collision>
</link>

<link name="rear_right_wheel_1">
  <inertial>
    <origin xyz="-0.2954245319318478 0.479185566775879 1.4090085518624756e-05" rpy="0 0 0"/>
    <mass value="0.4837051338981251"/>
    <inertia ixx="0.001358" iyy="0.000755" izz="0.000755" ixy="0.0" iyz="0.0" ixz="0.0"/>
  </inertial>
  <visual>
    <origin xyz="-0.1445 0.2396 -0.017" rpy="0 0 0"/>
    <geometry>
      <mesh filename="package://minmax_description/meshes/rear_right_wheel_1.stl" scale="0.001 0.001 0.001"/>
    </geometry>
    <material name="silver"/>
  </visual>
  <collision>
    <origin xyz="-0.1445 0.2396 -0.017" rpy="0 0 0"/>
    <geometry>
      <mesh filename="package://minmax_description/meshes/rear_right_wheel_1.stl" scale="0.001 0.001 0.001"/>
    </geometry>
  </collision>
</link>

<link name="front_right_wheel_1">
  <inertial>
    <origin xyz="-0.2954245363153505 -0.3271798313212245 -1.797019245908249e-08" rpy="0 0 0"/>
    <mass value="0.4837056531889683"/>
    <inertia ixx="0.001358" iyy="0.000755" izz="0.000755" ixy="-0.0" iyz="-0.0" ixz="0.0"/>
  </inertial>
  <visual>
    <origin xyz="-0.1445 -0.1636 -0.017" rpy="0 0 0"/>
    <geometry>
      <mesh filename="package://minmax_description/meshes/front_right_wheel_1.stl" scale="0.001 0.001 0.001"/>
    </geometry>
    <material name="silver"/>
  </visual>
  <collision>
    <origin xyz="-0.1445 -0.1636 -0.017" rpy="0 0 0"/>
    <geometry>
      <mesh filename="package://minmax_description/meshes/front_right_wheel_1.stl" scale="0.001 0.001 0.001"/>
    </geometry>
  </collision>
</link>

<link name="front_left_wheel_1">
  <inertial>
    <origin xyz="0.2954245319318478 -0.3272139793795933 1.4540475047942342e-05" rpy="0 0 0"/>
    <mass value="0.4837051338981271"/>
    <inertia ixx="0.001358" iyy="0.000755" izz="0.000755" ixy="0.0" iyz="0.0" ixz="0.0"/>
  </inertial>
  <visual>
    <origin xyz="0.1445 -0.1636 -0.017" rpy="0 0 0"/>
    <geometry>
      <mesh filename="package://minmax_description/meshes/front_left_wheel_1.stl" scale="0.001 0.001 0.001"/>
    </geometry>
    <material name="silver"/>
  </visual>
  <collision>
    <origin xyz="0.1445 -0.1636 -0.017" rpy="0 0 0"/>
    <geometry>
      <mesh filename="package://minmax_description/meshes/front_left_wheel_1.stl" scale="0.001 0.001 0.001"/>
    </geometry>
  </collision>
</link>

<link name="rear_left_wheel_1">
  <inertial>
    <origin xyz="0.2954245363153505 0.4791997178229248 2.0166712735948666e-05" rpy="0 0 0"/>
    <mass value="0.48370565318896697"/>
    <inertia ixx="0.001358" iyy="0.000755" izz="0.000755" ixy="-0.0" iyz="0.0" ixz="-0.0"/>
  </inertial>
  <visual>
    <origin xyz="0.1445 0.2396 -0.017" rpy="0 0 0"/>
    <geometry>
      <mesh filename="package://minmax_description/meshes/rear_left_wheel_1.stl" scale="0.001 0.001 0.001"/>
    </geometry>
    <material name="silver"/>
  </visual>
  <collision>
    <origin xyz="0.1445 0.2396 -0.017" rpy="0 0 0"/>
    <geometry>
      <mesh filename="package://minmax_description/meshes/rear_left_wheel_1.stl" scale="0.001 0.001 0.001"/>
    </geometry>
  </collision>
</link>

<joint name="Revolute 4" type="continuous">
  <origin xyz="0.1445 -0.2396 0.017" rpy="0 0 0"/>
  <parent link="base_link"/>
  <child link="rear_right_wheel_1"/>
  <axis xyz="-1.0 0.0 0.0"/>
</joint>

<joint name="Revolute 3" type="continuous">
  <origin xyz="0.1445 0.1636 0.017" rpy="0 0 0"/>
  <parent link="base_link"/>
  <child link="front_right_wheel_1"/>
  <axis xyz="1.0 -0.0 0.0"/>
</joint>

<joint name="Revolute 2" type="continuous">
  <origin xyz="-0.1445 0.1636 0.017" rpy="0 0 0"/>
  <parent link="base_link"/>
  <child link="front_left_wheel_1"/>
  <axis xyz="1.0 -0.0 0.0"/>
</joint>

<joint name="Revolute 1" type="continuous">
  <origin xyz="-0.1445 -0.2396 0.017" rpy="0 0 0"/>
  <parent link="base_link"/>
  <child link="rear_left_wheel_1"/>
  <axis xyz="-1.0 0.0 0.0"/>
</joint>

</robot>
